Workbook

Sheet CONTRATOS VIGENTES
A1: =TODAY() -> 46167
C2: TÉRMINO DA VIGÊNCIA | D2: CONTRATO | E2: ADITIVO | F2: FORNECEDOR | G2: SECRETARIA | H2: SECRETÁRIO | I2: GESTOR | J2: FISCAL | K2: OBJETO | L2: VIGÊNCIA | M2: DATA DA OS | N2: PERÍODO | O2: PROCESSO ADMINISTRATIVO | P2: PROCESSO EXECUÇÃO | Q2: AUDESP LICITAÇÃO | R2: AUDESP AJUSTE | S2: MODALIDADE LICITAÇÃO | T2: VALOR TOTAL CONTRATO | U2: ASSINATURA | V2: DATA DE PUBLICAÇÃO | W2: OBSERVAÇÃO
A3: CONTRATOS COM VENCIMENTO: MARÇO 2026
A4: =C4-$A$1 -> 310 | B4: =IF(A4<60,"Vencendo","Em Vigência") -> Em Vigência | C4: 46477 | D4: 12/24 | E4: 1º Aditivo | F4: LECASA PARTICIPAÇÕES E EMPREENDIMENTOS IMOBILIÁRIOS LTDA CNPJ - 21.091.888/0001-95 | G4: SAÚDE | H4: Felipe Vieira de Sá dos Santos CPF: 361.930.868-38 | I4: Alex Sandro Barroso Alves CPF: 303.636.638-51 | J4: Débora Gomes dos Santos CPF: 420.245.978-40 | K4: LOCAÇÃO DE IMÓVEL SITUADO NO MUNÍCIPIO DE RIO GRANDE DA SERRA, NA AVENIDA DOM PEDRO I ESQUINA COM A RUA VENÂNCIO ORSINI, PARA O FIM EXCLUSIVO DA INSTALAÇÃO DO CENTRO MÉDICO DE ESPECIALIDADE (CEME). | L4: 24 MESES | M4: - | N4: 01/04/26 A 31/03/28 | O4: 205/24 | P4: 779/24 | Q4: 2024000000150 | R4: 2024000000196 | S4: INEX 04/24 | T4: 336000 | U4: 46113
A5: CONTRATOS COM VENCIMENTO: MAIO 2026
A6: =C6-$A$1 -> -2 | B6: =IF(A6<60,"Vencendo","Em Vigência") -> Vencendo | C6: 46165 | D6: 18/23 | E6: 2º Aditivo | F6: ESPAÇO 2 TECNOLOGIA E INFORMÁTICA LTDA EPP CNPJ - 09.066.243/0001-05 | G6: ADMINISTRAÇÃO | H6: MILTON DE SOUZA MARTINS - CPF/MF sob o nº. 107.599.858-12 | I6: Elias | J6: Fábio Eduardo Garcia | K6: CONTRATAÇÃO DE EMPRESA ESPECIALIZADA PARA PRESTAÇÃO DE SERVIÇOS DE LOCAÇÃO, POR MEIO DE DISPONIBILIDADE DE EQUIPAMENTOS (MULTIFUNCIONAIS) DESTINADOS À IMPRESSÃO, REPROGRAFIA E DIGITALIZAÇÃO DE DOCUMENTOS NAS DEPENDÊNCIAS DA PREFEITURA MUNICIPAL DE RIO GRANDE DA SERRA | L6: 12 MESES com cláusula resolutiva | N6: 24/05/25 a 23/05/26 | O6: 303/22 | P6: 1130/23 | Q6: 2023000000071 | R6: AJUSTE 2023000000269 1 TERMO ADITIVO 2023000000019 2 TERMO ADITIVO 2024000000039 3 TERMO ADITIVO 2025000000051 | S6: PP 25/23 | T6: 248220 | U6: 45800 | V6: 45810
A7: =C7-$A$1 -> 1 | B7: =IF(A7<60,"Vencendo","Em Vigência") -> Vencendo | C7: 46168 | D7: 16/25 | E7: Contrato | F7: MARIA CAPARROZ SANTINELLI | G7: ESPORTE | H7: Nikson Nonato Nascimento Andrade CPF 337.710.608-18 | I7: Nikson Nonato Nascimento Andrade CPF 337.710.608-18 | J7: Luana Aline dos Santos CPF 350.638.378-75 | K7: LOCAÇÃO DE IMÓVEL PARA ATENDIMENTO DO PROJETO DE ARTES MARCIAIS FAZER VALER | L7: 12 meses | N7: 26/05/2025 a 26/05/2026 | O7: 207/25 | P7: 996/25 | R7: 2025000000401 | S7: INEX 13/25 | T7: 51600 | U7: 45803 | V7: 45810
A8: =C8-$A$1 -> 1 | B8: =IF(A8<60,"Vencendo","Em Vigência") -> Vencendo | C8: 46168 | D8: 48/24 | E8: 1º Aditivo | F8: RENOV PAVIMENTAÇÃO E CONSTRUÇÕES LTDA | G8: OBRAS | H8: Wanderlei Felipe da Silva Junior | I8: Leila Andreassi de Castro | J8: Guilherme Tadeu Aparecido de Oliveira Dias do Prado | K8: CONTRATAÇÃO DE EMPRESA ESPECIALIZADA PARA INTERVENÇÕES URBANÍSTICAS NA RUA ARUJÁ – VILA CONDE SICILIANO, RECAPEAMENTO ASFÁLTICO E CONTENÇÃO NO MUNICÍPIO DE RIO GRANDE DA SERRA / SP | L8: 270 DIAS | M8: 45628 | N8: 29/08/25 A 26/05/2026 | O8: 1114/2024 | P8: 2265/2024 | Q8: 2024000000279 | R8: 2024000000642 1º TERMO ADITIVO 2025000000082 | S8: CO 06/24 | T8: 854235.15 | U8: 45897 | V8: 45898
A9: CONTRATOS COM VENCIMENTO: JUNHO 2026
A10: =C10-$A$1 -> 10 | B10: =IF(A10<60,"Vencendo","Em Vigência") -> Vencendo | C10: 46177 | D10: 17/25 | E10: Contrato | F10: 4F SOLUÇÕES EM TECNOLOGIA LTDA | G10: ADMINISTRAÇÃO | H10: MILTON DE SOUZA MARTINS - CPF/MF sob o nº. 107.599.858-12 | I10: ELIAS RODRIGUES DO PRADO CPF 227.197.288-45 | J10: ARTHUR GALDINO MARQUES CPF 535.998.138-50 | K10: CONTRATAÇÃO DE EMPRESA ESPECIALIZADA NO FORNECIMENTO DE 300 LICENÇAS DE SOFTWARE DE ANTIVÍRUS, ACOMPANHADAS DE SUPORTE TÉCNICO PELO PERÍODO DE 12 MESES | L10: 12 meses | N10: 04/06/25 a 04/06/25 | O10: 663/25 | P10: 1098/25 | Q10: 2025000000155 | R10: 2025000000406 | S10: DP 15/25 | T10: 39999 | U10: 45807 | V10: 45812
A11: =C11-$A$1 -> 11 | B11: =IF(A11<60,"Vencendo","Em Vigência") -> Vencendo | C11: 46178 | D11: 54/24 | E11: Contrato | F11: NELY RODRIGUES CONSTRUÇÕES CIVIS, COMÉRCIO E PRESTAÇÃO DE SERVIÇOS LTDA CNPJ sob o nº 01.969.162/0001-03 | G11: OBRAS | H11: Leandro Dias Florêncio CPF: 335.659.528-81 | I11: Leila Andreassi de Castro CPF: 235.681.298-92 | J11: Guilherme Tadeu Aparecido de Oliveira Dias do Prado CPF: 414.046.498-40 | K11: CONTRATAÇÃO DE EMPRESA ESPECIALIZADA PARA EXECUÇÃO DA PRAÇA ESPORTIVA NA RUA OSASCO - RECANTO DAS FLORES NO MUNICÍPIO DE RIO GRANDE DA SERRA/SP | L11: 210 DIAS | N11: 05/11/25 A 05/06/26 | O11: 1113/2024 | P11: 2239/2025 | Q11: 2024000000291 | R11: AJUSTE 2025000000587 | S11: CP 08/24 | T11: 198900 | U11: 45631 | V11: 45966 | W11: AUTORIZADO O ANDAMENTO DO PROCESSO SOMENTE EM 05/11/2025.
A12: =C12-$A$1 -> 17 | B12: =IF(A12<60,"Vencendo","Em Vigência") -> Vencendo | C12: 46184 | D12: 30/22 | E12: 4º Aditivo | F12: WHITE MARTINS GASES INDUSTRIAIS LTDA CNPJ: 35.820.448/0081-10 | G12: SAÚDE | H12: FELIPE VIEIRA DE SÁ DOS SANTOS CPF sob o nº 361.930.868-38 | I12: Aline Lima da Silva Toledo | J12: Telma Moraes Pires | K12: CONTRATAÇÃO DE EMPRESA ESPECIALIZADA PARA FORNECIMENTO CONTÍNUO E ININTERRUPTO DE OXIGÊNIO GASOSO EM CILINDROS COM LOCAÇÃO DE CILINDROS PARA ATENDER AS UNIDADES DE SAÚDE E UPA - UNIDADE DE PRONTO ATENDIMENTO | L12: 180 dias | M12: 45276 | N12: 13/12/25 A 11/06/26 | O12: 1475/22 | P12: 2451/22 | Q12: 2022000000126 | R12: 2022000000409 2º TERMO ADITIVO 2025000000025 3º TERMO ADITIVO 2025000000065 4º TERMO ADITIVO 2026000000006 | S12: PP 31/22 | T12: 622152 | U12: 45824 | V12: 45853
A13: =C13-$A$1 -> 25 | B13: =IF(A13<60,"Vencendo","Em Vigência") -> Vencendo | C13: 46192 | D13: 07/26 | E13: Contrato | F13: HC COMERCIO E SERVICOS LTDA CNPJ/MF sob o nº 39.346.967/0001-65 | G13: EDUCAÇÃO | H13: VINÍCIUS BRUM DA SILVA CIN sob o nº 406.779.358-89 | I13: Mônica Mara Rodrigues | J13: Greyce Sueli de Miranda Lima Paula | K13: AQUISIÇÃO DE KITS DE UNIFORMES ESCOLARES | L13: 03 meses | M13: - | N13: 19/03/26 a 19/06/26 | O13: 89/26 | P13: - | Q13: 2026000000003 | R13: 2026000000008 | S13: ADESÃO ATA 39/24 TABOÃO DA SERRA | T13: 815510.94 | U13: 46100 | V13: 46101
A14: =C14-$A$1 -> 32 | B14: =IF(A14<60,"Vencendo","Em Vigência") -> Vencendo | C14: 46199 | D14: 19/24 | E14: Contrato | F14: FL CONTROLE DE PRAGAS E SERVIÇO GERAIS LTDA RUA JOÃO THEODORO, 131, CENTRO CIDADE JACAREÍ/SP CEP: 12.308-720 | G14: Cidadania | H14: ELSA DOS ANJOS IWASAKI | I14: FERNANDA STACHOWSKI | J14: CIBELY APARECIDA MIRANDA DOS SANTOS | K14: CONTRATAÇÃO DE EMPRESA PARA PRESTAÇÃO DE SERVIÇOS DE DEDETIZAÇÃO E DESRATIZAÇÃO, SENDO 02 (DUAS) APLICAÇÕES COM INTERVALO DE 06 (SEIS) MESES, COM O EFETIVO CONTROLE DE PRAGAS, DAS ÁREAS INTERNAS E EXTERNAS DAS UNIDADES: CRAS, CREAS, SAICA (SERVIÇO DE ACOLHIMENTO INSTITUCIONAL PARA CRIANÇAS E ADOLESCENTES), CONSELHO TUTELAR, E DA SEDE DA SECRETARIA DA FAMÍLIA E DESENVOLVIMENTO SOCIAL | L14: 12 MESES | N14: 26/06/2025 A 26/06/2026 | O14: 144/2025 | P14: 1242/2025 | Q14: NÃO SE APLICA | R14: NÃO SE APLICA | S14: DP 16/23 | T14: 3000 | U14: 45826 | V14: 45834
A15: =C15-$A$1 -> 33 | B15: =IF(A15<60,"Vencendo","Em Vigência") -> Vencendo | C15: 46200 | D15: 14/22 | E15: 3º Aditivo | F15: CESPRO PROCESSAMENTO DE DADOS LTDA CNPJ - 17.875.435/0001-82 | G15: JURÍDICO | H15: Fábio Nunes Fernandes | I15: Elaine de Souza Pereira | J15: Jairson Virginio dos Santos | K15: SERVIÇOS DE CONSOLIDAÇÃO DA LEGISLAÇÃO MUNICIPAL, DE MODO INFORMATIZADO, PARA UTILIZAÇÃO VIA INTERNET | L15: 12 meses | N15: 27/06/25 a 27/06/26 | O15: 197/22 | P15: 1456/22 | Q15: 2022000000072 | R15: 3º TERMO ADITIVO 2025000000067 | S15: DP 06/22 | T15: 3480 | U15: 45835 | V15: 45841
A16: CONTRATOS COM VENCIMENTO: JULHO 2026
A17: =C17-$A$1 -> 38 | B17: =IF(A17<60,"Vencendo","Em Vigência") -> Vencendo | C17: 46205 | D17: 45/23 | E17: 3º Aditivo | F17: RENOV PAVIMENTAÇÃO E CONSTRUÇÕES LTDA - EPP CNPJ - 2024000000071 | G17: OBRAS | H17: Wanderlei Felipe da Silva Junior | I17: LEILA ANDREASSI DE CASTRO | J17: Guilherme Tadeu Aparecido de Oliveira Dias do Prado | K17: CONTRATAÇÃO DE EMPRESA PARA EXECUÇÃO DE PAVIMENTAÇÃO, DRENAGEM E SINALIZAÇÃO VIÁRIA - RUA CAMPOS SALES E RUA VALINHOS NO MUNICÍPIO DE RIO GRANDE DA SERRA | L17: 450 DIAS | M17: 45215 | N17: 05/10/2025 a 02/07/2026 | O17: 1148/22 | P17: 1986/23 | Q17: 2023000000118 | R17: Ajuste 2023000000388 Aditivo 1 2024000000028 Aditivo 2 2025000000009 Aditivo 3 2025000000091 | S17: CO 08/23 | T17: 2437957.5 | U17: 45935 | V17: 45967 | W17: VIGENCIA A PARTIR DA ORDEM DE INICIO
A18: =C18-$A$1 -> 49 | B18: =IF(A18<60,"Vencendo","Em Vigência") -> Vencendo | C18: 46216 | D18: 56/24 | E18: Contrato | F18: UPC - URBANA PAULISTA CONSTRUTORA LTDA CNPJ: 23.094.219/0001-00 | G18: OBRAS | H18: Leandro Dias Florencio CPF: 335.659.528-81 | I18: Leila Andreassi de Castro CPF: 235.681.298-92 | J18: Guilherme Tadeu Aparecido de Oliveira Dias do Prado CPF: 414.046.498-40 | K18: CONTRATAÇÃO DE EMPRESA ESPECIALIZADA PARA EXECUÇÃO DE RECAPEAMENTO E PAVIMENTAÇÃO ASFÁLTICA COM SINALIZAÇÃO VIÁRIA HORIZONTAL – ÁREA CENTRAL: RUA PREFEITO CARLOS JOSÉ CARLSON, RUA PASTOR AQUILINO SARTORI, RUA VENÂNCIO ORSINI E RUA PEDRO BRACIALLI NO MUNICÍPIO DE RIO GRANDE DA SERRA – SP | L18: 15 MESES | M18: 46126 | N18: 14/04/2024 A 13/07/2026 | O18: 1208/2024 | P18: 301/2025 | Q18: 2024000000301 | R18: 2025000000195 REEVIADO AUDESP VIGÊNCIA A PARTIR DA OS 2026000000072 | S18: CE 11/24 | T18: R$ 654.000,00 | U18: 45639 | V18: 45714
A19: CONTRATOS COM VENCIMENTO: AGOSTO 2026
A20: =C20-$A$1 -> 70 | B20: =IF(A20<60,"Vencendo","Em Vigência") -> Em Vigência | C20: 46237 | D20: 12/20 | E20: 5º Aditivo | F20: MARCIA ANDREA ZUCCO NISHIKAWARA CPF - 251.418.818-06 | G20: SAÚDE | H20: FELIPE VIEIRA DE SÁ DOS SANTOS | I20: Paula Azevedo Lopes | J20: Bianca Dantas Jacob | K20: LOCAÇÃO DE IMÓVEL SITUADO A RUA PREFEITO JOSÉ CARLSON, 07 - CENTRO - PARA ATENDER AS INSTALAÇÕES DO CAPS - CENTRO DE ATENÇÃO PSICOSSOCIAL | L20: 12 meses | N20: 03/08/24 a 03/08/25 | O20: 1987/19 | P20: 1418/20 | R20: 5º TERMO ADITIVO 2025000000075 | S20: DP 9/2020 | T20: 66420 | U20: 45870 | V20: 45904
A21: =C21-$A$1 -> 72 | B21: =IF(A21<60,"Vencendo","Em Vigência") -> Em Vigência | C21: 46239 | D21: 16/22 | E21: 3º Aditivo | F21: MARIA SANTOS SILVA CPF - 097.374.208-96 | G21: CIDADANIA | H21: Elza Dos Anjos Iwasaki | I21: Ilana Rodrigues Mariano | J21: Fernanda Stachowski | K21: LOCAÇÃO DE IMÓVEL SITO A RUA JOSE MARIA DE FIGUEIREDO, 575 - VILA GONÇALVES - RIO GRANDE DA SERRA/SP, ONDE ESTA INSTALADO O CREAS - CENTRO DE REFERENCIA DE ASSISTENCIA SOCIAL | L21: 12 meses | M21: 44778 | N21: 05/08/25 A 05/08/26 | O21: 930/22 | P21: 1583/22 | Q21: 2022000000091 | R21: 2024000000035 3º TERMO ADITIVO 2025000000069 | S21: DP 9/22 | T21: 38738.28 | U21: 45866 | V21: 45867
A22: =C22-$A$1 -> 80 | B22: =IF(A22<60,"Vencendo","Em Vigência") -> Em Vigência | C22: 46247 | D22: 34/24 | E22: 2º Aditivo | F22: RENOV PAVIMENTAÇÃO E CONSTRUÇÕES LTDA - EPP - | G22: OBRAS | H22: Wanderlei Felipe da Silva Junior | I22: LEILA ANDREASSI DE CASTRO | J22: Guilherme Tadeu Aparecido de Oliveira Dias do Prado | K22: CONTRATAÇÃO DE EMPRESA ESPECIALIZADA PARA EXECUÇÃO DE PAVIMENTAÇÃO ASFÁLTICA, DRENAGEM E SINALIZAÇÃO VIÁRIA – RUA JOAQUIM LOPES – BAIRRO VILA LOPES, NO MUNICÍPIO DE RIO GRANDE DA SERRA/SP | L22: 360 | M22: 45614 | N22: 18/08/2025 A 13/08/2026 | O22: 638/2024 | P22: 1612/2024 | Q22: 2024000000232 | R22: 2024000000602 1º aditivo 2025000000083 2º aditivo | S22: CP 04/24 | T22: 1996000 | U22: 45960 | V22: 45967
A23: =C23-$A$1 -> 81 | B23: =IF(A23<60,"Vencendo","Em Vigência") -> Em Vigência | C23: 46248 | D23: 32/23 | E23: 1º Aditivo | F23: N.K. FIBER LINK LTDA CNPJ - 29.845.988/0001-71 | G23: ADMINISTRAÇÃO | H23: Alex Sandro | I23: Elias Rodrigues do Prado | J23: Fabio Eduardo Garcia | K23: LOCAÇÃO DE CIRCUITO DE VÍDEO-MONITORAMENTO NAS DEPENDÊNCIAS DA PREFEITURA MUNICIPAL DE RIO GRANDE DA SERRA | L23: 12 meses | N23: 14/08/24 A 14/08/25 | O23: 680/23 | P23: 1805/23 | Q23: 2023000000106 | R23: 2023000000361 | S23: CD 161/23 | T23: 17280 | U23: 45511 | V23: 45156
E24: 2º Aditivo | H24: Milton de Souza Martins | I24: Elias Rodrigues do Prado | J24: Fabio Eduardo Garcia | L24: 12 meses | N24: 14/08/25 A 14/08/26 | R24: 2025000000079 | T24: 17280 | U24: 45883 | V24: 45910
A25: =C25-$A$1 -> 95 | B25: =IF(A25<60,"Vencendo","Em Vigência") -> Em Vigência | C25: 46262 | D25: 36/23 | E25: 2º Aditivo | F25: NARCISIO CALASANS VIEIRA CPF - 124.629.878-35 | G25: SAÚDE | H25: Felipe Vieira de Sá dos Santos | I25: Maria Olivia Paulino Torres Portugal | J25: Sandra Emidio da Silva Calheiros | K25: LOCAÇÃO DE IMÓVEL SITO À RUA CEARÁ, 261 - VILA SÃO JOÃO, ONDE ESTÁ INSTALADO A UNIDADE BÁSICA DE SAÚDE - VILA SÃO JOÃO | L25: 12 meses | M25: 45166 | N25: 28/08/25 A 28/08/26 | O25: 751/20 | P25: 1776/23 | R25: 2º TERMO ADITIVO 2025000000073 | S25: DP 16/23 | T25: 18145.56 | U25: 45896 | V25: 45905
A26: =C26-$A$1 -> 96 | B26: =IF(A26<60,"Vencendo","Em Vigência") -> Em Vigência | C26: 46263 | D26: 30/24 | E26: 1º Aditivo | F26: INNOVAMED MANUTENÇÃO DE EQUIPAMENTOS MÉDICOS LTDA CNPJ - 59.055.921/0001-02 | G26: SAÚDE | H26: FELIPE VIEIRA DE SÁ DOS SANTOS | I26: Silvana Moraes Branco Conceição | J26: UBS CENTRO FISCAL DO CONTRATO: Laize Aparecida Mendes UBS VILA NIWA FISCAL DO CONTRATO: Ana Paula de Matos Merlos Pompeo UBS SÃO JOÃO FISCAL DO CONTRATO: Maria Olivia Paulino Torres Portugal UBS SITIO MARIA JOANA FISCAL DO CONTRATO: Nathalia Pimentel Felintro UBS VILA CONDE FISCAL DO CONTRATO: Giselda Souza Batista Pereira UBS VILA LOPES FISCAL DO CONTRATO: Celia Barbosa Lima UBS SANTA TEREZA FISCAL DO CONTRATO: Aparecida Patrícia Pereira de Abreu Vieira UBS PARQUE AMÉRICA FISCAL DO CONTRATO: Odalia de Souza Cruz da Silva UPA FISCAL DO CONTRATO: Drielly Rodrigues Faustino Santos CAPS FISCAL DO CONTRATO: Paula Azevedo Lopes | K26: CONTRATAÇÃO DE EMPRESA ESPECIALIZADA PARA MANUTENÇÃO PREVENTIVA E CORRETIVA DE EQUIPAMENTOS ODONTOLÓGICOS E MÉDICO-HOSPITALARES BEM COMO A INSTALAÇÃO DE NOVOS EQUIPAMENTOS QUE SEJAM ADQUIRIDOS E INCORPORADOS A COBERTURA CONTRATUAL, NA REDE DE SAÚDE DE RIO GRANDE DA SERRA, PARA ATENDER A SECRETARIA MUNICIPAL DE SAÚDE | L26: 12 MESES | M26: 45533 | N26: 29/08/25 A 29/08/26 | O26: 324/24 | P26: 1670/24 | Q26: 2024000000224 | R26: 2024000000486 ADITIVO 1 2025000000077 | S26: PE - 13/24 | T26: 235500 | U26: 45898 | V26: 45931 | W26: PRORROGAÇÃO E ACRÉSCIMO DE 25%
A27: =C27-$A$1 -> 97 | B27: =IF(A27<60,"Vencendo","Em Vigência") -> Em Vigência | C27: 46264 | D27: 38/23 | E27: 2º Aditivo | F27: REDE SOL FUEL DISTRIBUIDORA S/A CNPJ - 02.913.444/0001-43 | G27: S. URBANOS | H27: Jefferson Crispim de Souza | I27: Michele Aparecida de Sousa Carneiro CPF: 457.917.218-38 | J27: Guilherme Leandro Bernardo CPF: 335.305.768-40 | K27: CONTRATAÇÃO DE EMPRESA PARA FORNECIMENTO PARCELADO DE COMBUSTÍVEIS DO TIPO GASOLINA COMUM E ÓLEO DIESEL BS10, COM MAIOR PERCENTUAL DE DESCONTO SOBRE O PREÇO MÉDIO MENSAL DIVULGADO PELA ANP (AGÊNCIA NACIONAL DO PETRÓLEO) PRATICADOS NO ESTADO DE SÃO PAULO, TENDO COMO REFERÊNCIA O PREÇO MÉDIO DA REGIÃO DO ABC OS MUNICÍPIOS DE RIBEIRÃO PIRES, MAUÁ E SANTO ANDRÉ PARA ABASTECIMENTO NO TANQUE DE COMBUSTÍVEL INSTALADO NA GARAGEM MUNICIPAL DA PREFEITURA MUNICIPAL DE RIO GRANDE DA SERRA | L27: 12 meses | N27: 30/08/25 a 30/08/26 | O27: 977/23 | P27: 1768/23 | Q27: 2023000000103 | R27: 2023000000358 1º TERMO ADITIVO 2024000000037 2º TERMO ADITIVO 2025000000086 | S27: PP 36/23 | T27: 277300 | U27: 45898 | V27: 45915 | W27: 1% DE DESCONTO NEGOCIAÇÃO
T28: 532400
T29: =SUM(T27:T28) -> 809700
A30: CONTRATOS COM VENCIMENTO: SETEMBRO 2026
A31: =C31-$A$1 -> 102 | B31: =IF(A31<60,"Vencendo","Em Vigência") -> Em Vigência | C31: 46269 | D31: 37/23 | E31: 1º Aditivo | F31: P&P COLIBRI – CONSULTORIA E SOLUÇÕES S/S LTDA CNPJ - 15.417.725/0001-57 | G31: COMUNICAÇÃO | H31: JULIANA | I31: Ualisson Henrique de Oliveira Monteiro | J31: Juciane da Penha Silva | K31: CONTRATAÇÃO DE EMPRESA PARA FORNECIMENTO DE SOFTWARE PARA ESTRUTURAÇÃO DE IMPRENSA OFICIAL DO MUNICÍPIO | L31: 12 MESES | N31: 04/09/24 A 04/09/25 | O31: 1549/23 | P31: 1893/23 | R31: 2023000000371 1º ADITIVO 2024000000040 | S31: CD 192/23 | T31: 7800 | U31: 45533 | V31: 45187
E32: 2 º Aditivo | H32: DANILO SILVEIRA DE LIMA CPF: 415.016.588-24 | I32: Douglas Ferreira Bombana CPF: 296.491.178-90 | J32: Jéssica Cristine Alves Pereira CPF: 385.599.468-45 | L32: 12 MESES | N32: 04/09/25 A 04/09/26 | T32: 7800 | U32: 45904 | V32: 45904
A33: =C33-$A$1 -> 109 | B33: =IF(A33<60,"Vencendo","Em Vigência") -> Em Vigência | C33: 46276 | D33: 32/25 | E33: Contrato | F33: RIOMEDICA SAÚDE E NUTRIÇÃO COMÉRCIO DE SUPLEMENTOS LTDA ME CNPJ/MF sob o nº 35.578.077/0001-28 | G33: SAÚDE | H33: FELIPE VIEIRA DE SÁ DOS SANTOS CPF sob o nº 361.930.868-38 | I33: Heloísa Pereira da Silva CPF: 434.113.338-12 | J33: Sara de Melo Silva Fernandes CPF: 448.006.058-81 | K33: AQUISIÇÃO DE SUPLEMENTO ALIMENTAR PARA ATENDIMENTO DE PACIENTE DA FARMÁCIA DE DEMANDA JUDICIAL DA SECRETARIA DE SAÚDE DE RIO GRANDE DA SERRA | L33: 12 meses | N33: 11/09/25 a 11/09/26 | O33: 1455/25 | P33: 1897/2025 | Q33: 2025000000187 | R33: 2025000000604 | S33: Dispensa nº 30/2025 | T33: 9360 | U33: 45909 | V33: 45911 | W33: VIGENCIA A PARTIR DA PUBLICAÇÃO
A34: =C34-$A$1 -> 109 | B34: =IF(A34<60,"Vencendo","Em Vigência") -> Em Vigência | C34: 46276 | D34: 36/25 | E34: Contrato | F34: FORTALEZA REAL COMERCIAL DE MATERIAIS E MANUTENÇÃO EM GERAL LTDA - ME CNPJ/MF sob o nº. 20.661.647/0001-71 | G34: SAÚDE | H34: FELIPE VIEIRA DE SÁ DOS SANTOS CPF sob o nº 361.930.868-38 | I34: Silvana Moraes Branco Conceição CPF: 140.431.098-30 | J34: Telma Moraes Pires CPF: 263.971.178-47 | K34: AQUISIÇÃO DE KITS ODONTOLÓGICOS – PROGRAMA SAÚDE NA ESCOLA | L34: 12 meses | N34: 11/09/25 a 11/09/26 | O34: 707/25 | P34: 2017/2025 | Q34: 2025000000189 | R34: 2025000000605 | S34: Dispensa nº 08/2025 | T34: 27400 | U34: 45909 | V34: 45911 | W34: VIGENCIA A PARTIR DA PUBLICAÇÃO
A35: =C35-$A$1 -> 110 | B35: =IF(A35<60,"Vencendo","Em Vigência") -> Em Vigência | C35: 46277 | D35: 01/23 | E35: 4º Aditivo | F35: VIAPRECISA TERRAPLENAGEM E PAVIMENTAÇÃO LTDA CNPJ - 31.133.672/0001-07 | G35: OBRAS | H35: WANDERLEI FELIPE DA SILVA JUNIOR CPF 179.165.208-50 | I35: LEILA ANDREASSI DE CASTRO CPF 235.681.298-92 | J35: SAMUEL PEREIRA MATOS SILVA CPF 382.138.398-46 | K35: CONTRATAÇÃO DE EMPRESA PARA EXECUÇÃO DE PAVIMENTAÇÃO, DRENAGEM E SINALIZAÇÃO VIÁRIA DAS RUAS: XAVANTES, PRESIDENTE PRUDENTE E COTIA – BAIRRO PARQUE AMÉRICA NO MUNICÍPIO DE RIO GRANDE DA SERRA | L35: 8 MESES | M35: 44970 | N35: 13/01/2026 À 12/09/2026 | O35: 1147/22 | P35: 309/23 | Q35: 2023000000012 | R35: 2023000000099 2º TERMO ADITIVO 2024000000056 3º TERMO ADITIVO 2025000000056 4º TERMO ADITIVO 2026000000019 | S35: CO 01/22 | T35: 712236.09 | U35: 45790 | V35: 45834 | W35: ORDEM DE INÍCIO 13/02/2023
A36: =C36-$A$1 -> 111 | B36: Em Vigência | C36: 46278 | D36: 31/25 | E36: 1º Aditivo | F36: MARIA DOS REMEDIOS DE SOUSA ALVES | G36: CIDADANIA | H36: Kátia Néris da Silva CPF 161.660.908-21 | I36: Fernanda Stachowski CPF 336.725.538-67 | J36: Rodrigo do Carmo Santos CPF 477.987.948-59 | K36: LOCAÇÃO DO IMÓVEL PARA INSTALAÇÃO DA CASA DE ACOLHIMENTO TEMPORÁRIA PARA PESSOAS EM SITUAÇÃO DE RUA | L36: 07 MESES | N36: 14/02/2026 À 13/09/2026 | O36: 357/2025 | P36: 1616/2025 | Q36: 2025000000183 | R36: 2025000000559 ADITIVO 1 2026000000012 | S36: INEX 15/2025 | T36: 28000 | U36: 46067 | V36: 46278
A37: =C37-$A$1 -> 123 | B37: =IF(A37<60,"Vencendo","Em Vigência") -> Em Vigência | C37: 46290 | D37: *** | E37: *** | F37: SINDICATO DOS SERVIDORES PÚBLICOS RIO GRANDE DA SERRA CNPJ: 53.721.247/0001-63 | G37: ADMINISTRAÇÃO | H37: MILTON DE SOUZA MARTINS CPF: 107.599.858-12 | K37: TERMO DE COOPERAÇÃO TÉCNICA - FORNECIMENTO E A ADMINISTRAÇÃO DO PLANO DE ASSISTÊNCIA MÉDICA - REPASSE AO SINDICATO REFERENTE AO CONVÊNIO MÉDICO - AUXILIO PATRONAL + AUXILIO PATRONAL FUNPREV | L37: 12 MESES | M37: *** | N37: 12/09/2025 A 11/09/2026 | O37: 1324/2023 | P37: 2015/2023 | Q37: NÃO SE APLICA | R37: NÃO SE APLICA | S37: **** | T37: 840000 | U37: 45912 | V37: 45932 | W37: CONVENIO COM SINDICATO
H38: ALEX SANDRO BARROSO ALVES | L38: 12 MESES | M38: *** | N38: 11/09/2024 À 11/09/2025 | T38: 840000 | U38: 45546 | V38: 45610 | W38: CONVENIO COM SINDICATO
H39: ALEXSANDRA SILVA AGUIAR | I39: IASMIN MARIA DA SILVA | J39: IASMIN MARIA DA SILVA | L39: 12 MESES | M39: *** | N39: 11/09/2023 A 11/09/2024 | T39: 800000 | U39: 45180 | V39: *** | W39: CONVENIO COM SINDICATO
A40: =C40-$A$1 -> 123 | B40: =IF(A40<60,"Vencendo","Em Vigência") -> Em Vigência | C40: 46290 | D40: 42/23 | E40: 3º Aditivo | F40: ANGELUS COMERCIAL E CONSULTORIA EM TECNOLOGIA EIRELI CNPJ - 31.260.520/0001-67 | G40: CIDADANIA | H40: Elza Dos Anjos Iwasaki CPF: 124.538.988-25 | I40: Fernanda Stachowski CPF: 336.725.538-67 | J40: Cibely Aparecida Miranda dos Santos CPF: 462.455.488-45 | K40: FORNECIMENTO DE GÊNEROS ALIMENTÍCIOS, COM ENTREGA FRACIONADA, VISANDO ATENDER ÀS NECESSIDADES DO SAICA – SERVIÇO DE ACOLHIMENTO INSTITUCIONAL PARA CRIANÇAS E ADOLESCENTES | L40: 12 MESES | N40: 25/09/25 À 25/09/26 | O40: 1104/23 | P40: 1937/23 | Q40: 2023000000112 | R40: ADITIVO 1 2024000000051 ADITIVO 2 2024000000058 ADITIVO 3 2025000000087 | S40: PP 39/23 | T40: 92896.16 | U40: 45925 | V40: 45944
...

Sheet CONTRATOS ENCERRADOS
A1: =TODAY() -> 46167
A2: TÉRMINO DA VIGÊNCIA | B2: CONTRATO | C2: ADITIVO | D2: FORNECEDOR | E2: SECRETARIA | F2: SECRETÁRIO | G2: GESTOR | H2: FISCAL | I2: OBJETO | J2: VIGÊNCIA MESES | K2: PERÍODO | L2: PROCESSO ADMINISTRATIVO | M2: PROCESSO EXECUÇÃO | N2: AUDESP LICITAÇÃO | O2: AUDESP AJUSTE | P2: MODALIDADE LICITAÇÃO | Q2: VALOR TOTAL CONTRATO | R2: ASSINATURA ATUAL | S2: DATA DE PUBLICAÇÃO | T2: OBSERVAÇÃO
A3: 46161 | B3: 14/25 | C3: Contrato | D3: ATN CAMPOS COMÉRCIO, PRESTAÇÃO DE SERVIÇOS, IMPORTAÇÃO E EXPORTAÇÃO LTDA CNPJ/MF sob o nº 54.682.221/0001-16 | E3: CIDADANIA | F3: Elza dos Anjos Iwasaki | G3: Fernanda Stachowski | H3: Cibely Aparecida Miranda dos Santos | I3: CONTRATAÇÃO DE EMPRESA PARA CONFECÇÃO DE 03 (TRÊS) UNIDADES DE PLACAS DE IDENTIFICAÇÃO, INCLUINDO O DESENVOLVIMENTO DE ARTE E INSTALAÇÃO, PARA ATENDER ÀS NECESSIDADES DA SECRETARIA DA FAMÍLIA E DESENVOLVIMENTO SOCIAL | J3: 12 MESES | L3: 19/05/25 A 19/05/26 | M3: 547/25 | N3: - | O3: - | P3: - | Q3: DP 08/25 | R3: 3368.43 | S3: 45789 | T3: 45796
A4: 46155 | B4: 02/2026 | C4: CONTRATO | D4: SIMONI INDUSTRIA GRAFICA LTDA CNPJ/MF Sob o nº 37.652.289/0001-33 | E4: FAMÍLIA | F4: KÁTIA NÉRIS DA SILVA | G4: Fernanda Stachowski | H4: Rodrigo do Carmo Santos | I4: AQUISIÇÃO DE PLACAS DE IDENTIFICAÇÃO, BANNER, FOLDERS E DEMAIS MATERIAIS, COM A FINALIDADE DE ESTRUTURAR OS AMBIENTES DA SECRETARIA E SEUS EQUIPAMENTOS INCLUINDO O NOVO ESPAÇO DO CENTRO DE REFERÊNCIA DE ASSISTÊNCIA SOCIAL (CRAS) E FACILITAR O ACESSO DA POPULAÇÃO AOS SERVIÇOS OFERECIDOS | J4: 30 DIAS | L4: 14/04/2026 A 13/05/2026 | M4: 1901/2025 | N4: - | O4: 2026000000116 | P4: 2026000000158 | Q4: PE 39/2025 | R4: R$ 15.000,00 | S4: 46126 | T4: 46128
A5: 46170 | B5: 15/25 | C5: Contrato | D5: ATN CAMPOS COMÉRCIO, PRESTAÇÃO DE SERVIÇOS, IMPORTAÇÃO E EXPORTAÇÃO LTDA | E5: DESENVOLVIMENTO | F5: André Martins Caparroz CPF 292.921.258-69 | G5: Cristopher Ferraz Araujo CPF 228.469.558-24 | H5: Isabella Favero Fazani CPF 450.711.818-27 | I5: AQUISIÇÃO DE 02 (DOIS) TOTENS DE INFORMAÇÃO TURÍSTICA, A SEREM ALOCADOS EM ESPAÇOS ESTRATÉGICOS E DE GRANDE CIRCULAÇÃO NO MUNICÍPIO DE RIO GRANDE DA SERRA | J5: 12 meses | L5: 28/05/25 a 28/05/25 | M5: 386/25 | N5: 1164/2025 | O5: 2025000000149 | P5: 2025000000407 | Q5: DP 14/25 | R5: 11200 | S5: 45805 | T5: 45819 | U5: DESINTERESSE MANIFESTO POR E-MAIL EM 22/04/2026, ÀS 10:43 - QUARTA-FEIRA
A6: 46094 | B6: 09/24 | C6: Contrato | D6: ZENITE PROJETOS E CONSTRUÇÕES LTDA CNPJ: 46.294.771/0001-30 | E6: OBRAS | F6: KLEBER AVELINO DE OLIVEIRA CPF: 373.855.598-67 | G6: KLEBER AVELINO DE OLIVEIRA CPF: 373.855.598-67 | H6: JOÃO VICTOR SILVA CPF: 484.664.358-16 | I6: CONTRATAÇÃO DE EMPRESA PARA PRESTAÇÃO DE SERVIÇOS DE ELABORAÇÃO DE ESTUDO PRELIMINAR, PROJETOS BÁSICOS/EXECUTIVOS MULTIDISCIPLINARES PARA IMPLANTAÇÃO DO CONJUNTO HABITACIONAL E URBANIZAÇÃO, BEM COMO A ELABORAÇÃO DA DOCUMENTAÇÃO LEGAL E SERVIÇOS DE APROVAÇÃO EM TODOS OS ÓRGÃOS PÚBLICOS COMPETENTES PARA IMPLANTAÇÃO DO EMPREENDIMENTO RIO GRANDE DA SERRA | J6: 11 MESES | K6: 45425 | L6: 13/05/2024 A 13/04/2025 | M6: 1708/2023 | N6: 622/24 | O6: 2024000000138 | P6: 2024000000188 | Q6: CO 16/23 | R6: 210000 | S6: 45371 | T6: 45400
C7: 1º aditivo | F7: LEANDRO DIAS FLORÊNCIO CPF: 335.659.528-81 | G7: LEILA ANDREASSI DE CASTRO CPF: 235.681.298-92 | H7: GUILHERME TADEU APARECIDO DE OLIVEIRA DIAS DO PRADO CPF: 414.046.498-40 | J7: 11 MESES | L7: 13/04/2025 A 13/03/2026 | O7: 2024000000138 | Q7: CO 16/23 | S7: 45760 | T7: 45793 | U7: PRORROCAÇÃO SOMENTE DE PRAZO
A8: 46082 | B8: 48/25 | C8: Contrato | D8: PROJESOL ENGENHARIA LTDA CNPJ/MF sob o nº 38.517.835/0001 96 | E8: GOVERNO | F8: Maciel Manoel de Oliveira CPF: 131.613.048 70 | G8: Aline Macruz CPF: 379.914.218 56 | H8: Karine Roque Nascimento CPF: 389.766.778 97 | I8: CONTRATAÇÃO DE EMPRESA(S) ESPECIALIZADA(S) NA PRESTAÇÃO DE SERVIÇOS DE TOPOGRAFIA E SONDAGEM PARA IMPLANTAÇÃO DE UNIDADES HABITACIONAIS MINHA CASA, MINHA VIDA FHNIS SUB 50 | J8: 03 MESES | L8: 01/12/2025 A 01/03/2025 | M8: 2241/2025 | N8: 2212/2025 | P8: AJUSTE 2025000000809 | Q8: DP Nº 41/25 | R8: 24888.88 | S8: 45992 | T8: 45992
A9: 46073 | B9: 33/23 | C9: 2º Aditivo | D9: VIAPRECISA TERRAPLANAGEM E PAVIMENTAÇÃO LTDA CNPJ - 31.133.672/0001-07 | E9: OBRAS | F9: Leandro Dias Florencio | G9: Leila Andreassi de Castro | H9: Leandro Dias Florencio | I9: CONTRATAÇÃO DE EMPRESA PARA EXECUÇÃO DE PAVIMENTAÇÃO, DRENAGEM E SINALIZAÇÃO DE VIA URBANA – CHÁCARA SÃO PAULO | J9: 270 DIAS | K9: 45173 | L9: 26/05/25 A 20/02/26 | M9: 1864/22 | N9: 1552/23 | O9: 2023000000099 | P9: AJUSTE 2023000000344 1º ADITIVO 2024000000032 2º ADITIVO 2025000000055 | Q9: CO 9/23 | R9: 743798.67 | S9: 45803 | T9: 45834
A10: 46066 | B10: 01/25 | C10: Contrato | D10: ATIVA HEALTH SERVIÇOS MÉDICOS LTDA CNPJ: 35.697.111/0001-83 | E10: SAÚDE | F10: Felipe Vieira de Sá dos Santos CPF: 361.930.868-38 | G10: Alessandro dos Santos Possidônio Silva CPF: 192.252.648-79 | H10: Telma Moraes Pires CPF: 263.971.178-47 | I10: CONTRATAÇÃO EMERGENCIAL DE EMPRESA PARA PRESTAÇÃO DE SERVIÇOS DE ASSISTÊNCIA À SAÚDE, COMPOSTOS POR ATIVIDADES MÉDICAS ASSISTENCIAIS, SERVIÇOS DE DIAGNÓSTICOS: RAIO-X, ULTRASSONOGRAFIA, MAMOGRAFIA E EXAMES LABORATORIAIS, COM FORNECIMENTO DE EQUIPAMENTOS E MÃO DE OBRA, EXCETO APARELHO DE USG E MAMÓGRAFO QUE PERTENCEM A PREFEITURA MUNICIPAL DE RIO GRANDE DA SERRA, DESTINADOS À COMPLEMENTAR E ATENDER ÀS NECESSIDADES DAS UNIDADES BÁSICA DE SAÚDE, UPA – UNIDADE DE PRONTO ATENDIMENTO E CEME – CENTRO DE ESPECIALIDADES MÉDICAS DA SECRETARIA MUNICIPAL DE SAÚDE DE RIO GRANDE DA SERRA | J10: 06 meses | K10: 45701 | L10: 13/08/25 a 13/02/26 | M10: 212/2025 | N10: 346/2025 | O10: 2025000000122 | P10: 2025000000179 | Q10: DP 02/25 | R10: 8317509.3 | S10: 45882 | T10: 45895
A11: 46064 | B11: 32/24 | C11: 1º Aditivo | D11: LMM ENGENHARIA E SERVIÇOS LTDA CNPJ - 44.626.011/0001-57 | E11: OBRAS | F11: Wanderlei Felipe da Silva Junior | G11: Leila Andreassi de Castro | H11: Adriano de Sousa Pereira | I11: CONTRATAÇÃO DE EMPRESA ESPECIALIZADA EM ENGENHARIA OU ARQUITETURA PARA A ADAPTAÇÃO DE IMÓVEL DESTINADO AO CENTRO DE ESPECIALIDADES MÉDICAS (CEME) | J11: 360 DIAS | L11: 15/08/25 A 11/02/26 | M11: 531/24 | N11: 1602/24 | O11: 2024000000234 | P11: 2024000000461 1º aditivo 2025000000081 | Q11: CO 05/24 | R11: 814885 | S11: 45884
A12: 46272 | B12: 19/22 | C12: 3º Aditivo | D12: TULIO CASSAROTTI JUNIOR CPF - 155.335.868-65 | E12: CIDADANIA | F12: ELZA DOS ANJOS IWASAKI | G12: Fernanda Stachowski | H12: Cibely Aparecida Miranda dos Santos | I12: LOCAÇÃO DE IMÓVEL LOCALIZADO NA RUA SANTA BRANCA, Nº 24, JARDIM SANTA TEREZA, RIO GRANDE DA SERRA/SP, ONDE ESTÁ INSTALADO O CENTRO DE REFERENCIA DE ASSISTÊNCIA SOCIAL - CRAS, PARA ATENDER A SECRETARIA DE CIDADANIA E INCLUSÃO SOCIAL | J12: 12 meses | K12: CLÁUSULA RESOLUTIVA CONTRATO ENCERRADO | L12: 07/09/25 À 07/09/26 | M12: 1034/2022 | N12: 1675/2022 | P12: ADITIVO 3 2025000000084 | Q12: DP 15/22 | R12: 72000 | S12: 45905 | T12: 45930 | U12: CLÁUSULA RESOLUTIVA
A13: 46018 | B13: 45/24 | C13: 1º Aditivo | D13: VITÓRIA SERVIÇOS OPERACIONAIS LTDA CNPJ - 10.354.733/0001-88 | E13: OBRAS | F13: Leandro Dias Florêncio CPF: 335.659.528-81 | G13: João Victor Silva CPF: 484.664.358-16 | H13: Leandro Dias Florêncio CPF: 335.659.528-81 | I13: CONTRATAÇÃO DE EMPRESA ESPECIALIZADA EM ENGENHARIA PARA CONSTRUÇÃO DO TERMINAL RODOVIÁRIO MUNICIPAL NO MUNICÍPIO DE RIO GRANDE DA SERRA – ETAPA 07 | J13: 15 MESES | K13: 45572 | L13: 30/09/2024 A 30/12/2025 | M13: 343/24 | N13: 1867/2024 | O13: 2024000000258 | P13: 2024000000071 | Q13: CO 03/24 | R13: 3959514.2 | S13: 45632 | T13: 45632
A14: 46023 | B14: 39/25 | C14: CONTRATO sem renovação | D14: BIOLIFE MANUTENÇÃO DE EQUIPAMENTOS HOSPITALARES CNPJ:57.367.453/0001-78 | E14: SAÚDE | F14: Felipe Vieira de Sá dos Santos CPF: 361.930.868-38 | G14: Alessandro dos Santos Possidônio Silva CPF: 192.252.648-79 | H14: Telma Moraes Pires CPF: 263.971.178-47 | I14: CONTRATAÇÃO DE EMPRESA ESPECIALIZADA PARA A PRESTAÇÃO DE SERVIÇOS DE MANUTENÇÃO PREVENTIVA E CORRETIVA DOS VENTILADORES PULMONARES DA UNIDADE DE PRONTO ATENDIMENTO (UPA) DE RIO GRANDE DA SERRA | J14: 90 DIAS | L14: 03/10/2025 A 01/01/2026 | M14: 1246/25 | N14: 2018/2025 | O14: 2025000000201 | P14: AJUSTE 2025000000684 | Q14: INEX 17/25 | R14: 23050 | S14: 45658 | T14: 45933 | U14: VIGÊNCIA A PARTIR DA PUBLICAÇÃO
A15: 46011 | B15: 34/2022 | C15: 2º ADITIVO | D15: IGEVE - INSTITUTO DE GESTÃO EDUCACIONAL E VALORIZAÇÃO DO ENSINO CNPJ: 28.413.401/0001-92 | E15: EDUCAÇÃO E CULTURA | F15: ALESSANDRA AMORA BARCHINI | G15: LAMARTINE DOURADO CAVALCANTE | H15: COMISSÃO DE AVALIAÇÃO E MONITORAMENTO - PORTARIA 717/22 | I15: TERMO DE COLABORAÇÃO PARA O ATENDIMENTO DOS ALUNOS MATRICULADOS NA EDUCAÇÃO INFANTIL, BEM COMO A GESTÃO OPERACIONAL (NÃO PEDAGÓGICA) DAS UNIDADES ESCOLARES DE EJA (EDUCAÇÃO DE JOVENS E ADULTOS) E AEE (ATENDIMENTO EDUCACIONAL ESPECIALIZADO) E DE ENSINO FUNDAMENTAL 1. | J15: 12 MESES | K15: 44915 | L15: 20/12/2024 A 20/12/2025 | M15: 1881/2022 | N15: 2479/2022 | O15: NÃO SE TRATA DE PROCESSO LICITATÓRIO | P15: NÃO SE TRATA DE PROCESSO LICITATÓRIO | Q15: CHAMAMENTO PÚBLICO N° 02/22 - SEC | R15: 11201921
A16: 46009 | B16: 53/24 | C16: Contrato | D16: KONICA MINOLTA HEALTHCARE DO BRASIL INDÚSTRIA DE EQUIPAMENTOS MÉDICOS LTDA | E16: SAÚDE | F16: Luís Fernando Pinotti Silva | G16: VALQUIRIA HELENA DOS SANTOS GONÇALVES | H16: NADJA MARIA SANTOS SILVA | I16: AQUISIÇÃO DE MAMÓGRAFO VISANDO ATENDER A SECRETARIA MUNICIPAL DE SAÚDE | J16: 12 MESES | L16: 18/12/2024 A 18/12/2025 | M16: 487/2024 | O16: 2024000000297 | P16: 2025000000003 | Q16: PE 33/24 | R16: 849000 | S16: 45644 | T16: 45645
A17: 45983 | B17: 46/24 | C17: Contrato | D17: EDUARDO NELSON CANIL LTDA | E17: ADMINISTRAÇÃO/FINANÇAS | F17: Alex Sandro barroso Alves e Cassio Roberto de Souza Pegoraro | G17: Gilmar Santana dos Santos | H17: José Uiliam Loiola da Silva | I17: CONTRATAÇÃO DE ESCRITÓRIO DE ADVOCACIA ESPECIALIZADO NA PRESTAÇÃO DE ASSESSORIA E CONSULTORIA JURÍDICA A SECRETARIA ADMINISTRATIVA E DE FINANÇAS, COM O FIM ESPECÍFICO DE IMPOSTO DE RENDA, O QUAL FOI REPASSADO INDEVIDAMENTE E RECEITA FEDERAL | J17: 22/11/2024 A 22/11/2025 | L17: 22/11/2024 A 22/11/2025 | M17: 1993/2024 | N17: 2243/2024 | O17: - - - | P17: - - - | Q17: INEX N° 16/24 | R17: O valor equivalente a 20% (vinte por cento) do valor restituído. | S17: 45618
A18: 45978 | B18: 25/22 | C18: Contrato | D18: FUNDAÇÃO DE APOIO À UNIVERSIDADE MUNICIPAL DE SÃO CAETANO DO SUL CNPJ - 13.166.456/0001-78 | E18: ADMINISTRAÇÃO | F18: Alexsandra Silva Aguiar - CPF: 180.290.728-99 | G18: Suzana Lopes Quintão Silva - CPF: 277.740.328-78 | H18: Iasmin Maria da Silva - CPF: 390.280.658-30 | I18: CONTRATAÇÃO DE EMPRESA ESPECIALIZADA PARA PRESTAÇÃO DE SERVIÇOS DE REVISÃO DA ESTRUTURA ADMINISTRATIVA ORGANIZACIONAL DA PREFEITURA DE RIO GRANDE DA SERRA | J18: 12 Meses | K18: 44882 | L18: 17/11/22 a 17/11/23 | M18: 1660/22 | N18: 2358/22 | O18: LICITAÇÃO 2022000000118 | P18: 2022000000391 | Q18: DP 30/22 | R18: 300000 | S18: 44882 | T18: 44900
C19: 1º Aditivo | F19: Alexsandra Silva Aguiar - CPF: 180.290.728-99 | G19: Suzana Lopes Quintão Silva - CPF: 277.740.328-78 | H19: Marcela Barbosa Porto - CPF: 365.896.138-42 | J19: 12 Meses | L19: 17/11/23 a 17/11/24 | P19: 2024000000002 | S19: 45245 | T19: 45301 | U19: PRORROGAÇÃO DE VIGÊNCIA
C20: 2º Aditivo | F20: Alex Barroso Alves - CPF: 140.234.958-08 | G20: Alex Barroso Alves - CPF: 140.234.958-08 | H20: Gilmar Santana dos Santos - CPF: 381.836.618-74 | J20: 12 MESES | L20: 17/11/24 A 17/11/25 | P20: 2024000000072 | S20: 45610 | T20: 45629 | U20: PRORROGAÇÃO DE VIGÊNCIA
A21: =#REF!-$A$1 -> #REF! | B21: 47/24 | C21: RESCISÃO | D21: RENOV PAVIMENTAÇÃO E CONSTRUÇÕES LTDA | E21: OBRAS | F21: WANDERLEI | G21: - | H21: - | I21: CONTRATAÇÃO DE EMPRESA ESPECIALIZADA PARA EXECUÇÃO DE RECAPEAMENTO E PAVIMENTAÇÃO ASFÁLTICA COM SINALIZAÇÃO VIÁRIA HORIZONTAL – ÁREA CENTRAL LOCALIZADA NA AVENIDA DOM PEDRO I – CENTRO – RIO GRANDE DA SERRA/SP | J21: 300 DIAS | K21: FALTA OS | L21: OS | M21: 1155/2024 | N21: 2253/2024 | O21: 2024000000272 | P21: 2024000000628 | Q21: CO 07/24 | R21: 813280 | S21: 45980
A22: 45939 | B22: 40/23 | C22: 1º Aditivo | D22: PRODESP - COMPANHIA DE PROCESSAMENTO DE DADOS DO ESTADO DE SÃO PAULO - CNPJ: 62.577.929/0001-35 | E22: SEGURANÇA URBANA, TRANSITO E DEFESA CIVIL | F22: Izaias Fernandes | G22: Mauro Munhoz Martins Fernandes | H22: Alexandre de Lima Campos | I22: PRESTAÇÃO DE SERVIÇOS TECNICOS DE INFORMATICA REALTIVO A CESSÃO DE INFORMAÇÕES DO BANCO DE DADOS DO DETRAN PARA O PROCESSAMENTO DE MULTAS DE TRÂNSITO | J22: 12 MESES | K22: OS 09/10/2023 | L22: 09/10/2025 A 09/10/2026 | M22: 1566/2023 | N22: 2534/2023 | O22: ADITIVO 2023000000126 | P22: 2025000000022 | Q22: DP 15/23 | R22: 10310.4 | S22: 45573 | T22: 45744 | U22: PRORROGÁVEL NO LIMITE DE 60 MESES - LEI 8.666/93
A23: 45930 | B23: 41/24 | C23: Contrato | D23: GARLOC TRANSPORTES, LOGISTICA E LOCAÇÕES LTDA CNPJ - 69.205.789/0001-13 | E23: EDUCAÇÃO | F23: ALESSANDRA | G23: Lamartine Dourado Cavalcante | H23: Ari Inácio de Souza | I23: CONTRATAÇÃO DE EMPRESA ESPECIALIZADA PARA PRESTAÇÃO DE SERVIÇOS DE TRANSPORTE ESCOLAR PARA ALUNOS DO ENSINO FUNDAMENTAL MATRICULADOS NA REDE MUNICIPAL DE ENSINO DE RIO GRANDE DA SERRA | J23: 12 MESES | K23: 45566 | L23: 30/09/24 À 30/09/25 | M23: 2413/23 | N23: 1908/2024 | O23: 2024000000140 | P23: AJUSTE 2024000000570 | Q23: PP 54/23 | R23: 480000 | S23: 45565
A24: 45946 | B24: 39/24 | C24: Contrato | D24: COMPANHIA BRASILEIRA DE CARTUCHOS CNPJ - 57.494.031/0001-63 | E24: SEGURANÇA | F24: Yuri Laled Lobato El Malat | G24: João Vitor Rocha Amado | H24: Ariane Fajoli de Souza | I24: AQUISIÇÃO DE MUNIÇÕES CBC 9MM LUGER ETOG 124GR E CBC 9MM LUGER+P EXPO 124GR BONDED A | J24: 16/10/2024 A 16/10/2025 | M24: 1360/2024 | N24: 2001/2024 | O24: 20244000000243 | P24: AJUSTE 2024000000594 | Q24: INEX 12/2024 | R24: 35750 | S24: 45561
A25: 45923 | B25: 18/25 | C25: Contrato | D25: FL CONTROLE DE PRAGAS E SERVIÇO GERAIS LTDA | E25: CIDADANIA | F25: ELSA DOS ANJOS IWASAKI | G25: CIBELY APARECIDA MIRANDA DOS SANTOS CPF: 462.455.488-45 | H25: FERNANDA STACHOWSKI | I25: CONTRATAÇÃO DE EMPRESA PARA PRESTAÇÃO DE SERVIÇOS DE LIMPEZA DE CAIXA D’AGUA DAS UNIDADES: CRAS, CREAS, SAICA, CONSELHO TUTELAR E DA SECRETARIA DA FAMÍLIA E DESENVOLVIMENTO SOCIAL | J25: 90 DIAS | L25: 23/06/2025 A 23/09/2025 | M25: 145/2025 | N25: 1217/2025 | O25: NÃO SE APLICA DEVIDO O VALOR | P25: NÃO SE APLICA DEVIDO O VALOR | Q25: DP 17/25 | R25: 1649.96 | S25: 45821 | T25: 45831
A26: 45913 | B26: 36/24 | C26: Contrato | D26: NP TECNOLOGIA E GESTÃO DE DADOS LTDA CNPJ: 07.797.967/0001-95 | E26: ADMINISTRAÇÃO | F26: Alex Sandro Barroso Alves | G26: Daniela Aparecida Ferreira Magalhães Terra | H26: Conceição Aparecida Trajano da Silva | I26: CONTRATAÇÃO DE EMPRESA ESPECIALIZADA NO FORNECIMENTO DE ASSINATURA DE FERRAMENTA DE PESQUISA E COMPARAÇÃO DE PREÇOS PRATICADOS PELA ADMINISTRAÇÃO PÚBLICA | J26: 12 MESES | K26: 45548 | L26: 13/09/24 À 13/09/2025 | M26: 890/2024 | N26: 1733/2024 | O26: 2024000000240 | P26: 2024000000519 | Q26: INX 10/24 | R26: 14950 | S26: 45545
A27: 45897 | B27: 24/24 | C27: Contrato | D27: FC GERADORES LTDA CNPJ - 27.117.171/0001-51 | E27: SAÚDE | F27: Luís Fernando Pinotti Silva | G27: Telma Moraes Pires | H27: Milton Luiz Rodrigues dos Santos | I27: CONTRATAÇÃO DE EMPRESA ESPECIALIZADA EM PRESTAÇÃO DE SERVIÇO DE MANUTENÇÃO PREVENTIVA E CORRETIVA PARA GRUPO DE GERADORES DA SECRETARIA MUNICIPAL DE SAÚDE – UNIDADE DE PRONTO ATENDIMENTO – UPA | J27: 12 meses | K27: - | L27: 28/08/24 A 28/08/25 | M27: 74/24 | N27: 1711/24 | O27: 2024000000246 | P27: 2024000000490 | Q27: CD 25/24 | R27: 5400 | S27: 45532
A28: 45891 | B28: 33/24 | C28: Contrato | D28: CAIXA ECONÔMICA FEDERAL CNPJ - 00.360.305/0001-04 | E28: OBRAS | F28: LEANDRO | G28: Leandro Dias Florêncio | H28: Gislene Stephanelli | I28: CONTRATAÇÃO DE EMPRESA ESPECIALIZADA PARA CAPACITAÇÃO DE SERVIÇOS TÉCNICOS NA MOBILIDADE OFICINA DE CAPACITAÇÃO COM OS TEMAS: ENGENHARIA DE CUSTOS – MOBILIDADE À DISTÂNCIA | J28: 12 meses | L28: 22/08/2024 A 22/08/2025 | M28: 1454/2024 | Q28: INEXIGIBILIDADE Nº 09/24 | R28: 4370 | S28: 45526
A29: 45874 | B29: 31/24 | C29: 1º Aditivo | D29: TBRT AUDITORES INDEPENDENTES S/S CNPJ - 03.566.241/0001-90 | E29: ADMINISTRAÇÃO | F29: MILTON DE SOUZA MARTINS - CPF/MF sob o nº. 107.599.858-12 | G29: ERIKA TIEMI SEKITANI - CPF: 127.071.258-65 | H29: BRUNA GABRIELLE RIBEIRO DE PAULA - CPF: 433.593.348-76 | I29: CONTRATAÇÃO DE EMPRESA ESPECIALIZADA NA CAPACITAÇÃO TÉCNICA COMPLETA DOS SERVIDORES PÚBLICOS NA ÁREA DE RECURSOS HUMANOS (DEPARTAMENTO PESSOAL) E NA EXECUÇÃO DO E-SOCIAL E DCTFWEB JUNTO AO DEPARTAMENTO DE PESSOAL, VISANDO CORRIGIR TODAS AS DEFICIÊNCIAS E REGULARIZAR OS LANÇAMENTOS, CUMPRINDO OS PRAZOS LEGAIS PREVISTOS. | J29: 06 meses | L29: 05/02/24 A 05/08/25 | M29: 410/24 | N29: 1556/24 | O29: 2024000000223 | P29: 2025000000069 | Q29: PE 19/2024 | R29: 162000 | S29: 45693 | T29: 45728 | U29: DIMINUIÇÃO DE 10% DO VALOR INICIAL DO CONTRATO
A30: 45868 | B30: 06/21 | C30: 5º Aditivo | D30: PEDRO LUIS DE OLIVEIRA CPF - 379.169.808-78 GILDETE PEREIRA DE OLIVEIRA CPF - 839.070.418-87 | E30: SEGURANÇA URBANA, TRANSITO E DEFESA CIVIL | F30: Izaias Fernandes CPF: 155.257.828-39 | G30: Elias de Lima Meneses CPF: 304.013.528-70 | H30: Fabiano Gomes Duarte CPF: 365.558.428-81 | I30: LOCAÇÃO DE IMÓVEL LOCALIZADO NA AV. JEAN LIEUTAUD, 309 -TÉRREO, 1º E 2º PAVIMENTO - JD. SANTA TEREZA - RGS/SP, ONDE SERÁ INSTALADO A SECRETARIA DE SEGURANÇA URBANA, TRANSITO E DEFESA CIVIL E A GUARDA MUNICIPAL | J30: 6 MESES | L30: 30/01/25 à 30/07/25 | M30: 197/2021 | N30: 698/2021 | O30: 2021000000097 | P30: AJUSTE 2022000000056 4 ADITIVO 2025000000003 5 ADITIVO 2025000000012 | Q30: DP 06/21 | R30: 48000 | S30: 45687 | T30: 45694
A31: 45864 | B31: 29/23 | C31: 1º Aditivo | D31: ROCHA E MACHADO SOCIEDADE DE ADVOGADOS CNPJ - 19.851.544/0001-95 | E31: JURÍDICO | F31: Fábio Nunes Fernandes | G31: Elaine de Souza Pereira | H31: Jairson Virginio dos Santos | I31: CONTRATAÇÃO DE EMPRESA ESPECIALIZADA PARA PRESTAÇÃO DE SERVIÇOS ADVOCATÍCIOS DESTINADOS À ASSESSORIA JURÍDICA, BEM COMO DEFESA TÉCNICA DA PREFEITURA DO MUNICÍPIO DE RIO GRANDE DA SERRA NOS PROCESSOS E PROCEDIMENTOS EM TRÂMITE NO EGRÉGIO TRIBUNAL DE CONTAS DO ESTADO DE SÃO PAULO, INCLUINDO O ACOMPANHAMENTO DOS PROCEDIMENTOS ATÉ SEU TRÂNSITO EM JULGADO | J31: 12 MESES | L31: 26/07/24 a 26/07/25 | M31: 493/23 | N31: 1514/23 | O31: 2023000000095 | P31: 1º ADITIVO 2024000000029 AJUSTE 2023000000338 | Q31: CV 06/23 | R31: 170388 | S31: 45133 | T31: 45139
A32: 45857 | B32: 28/23 | C32: 1º Termo Aditivo | D32: PRESCON INFORMÁTICA E ASSESSORIA LTDA CNPJ - 01.221.551/0001-48 | E32: ADMINISTRAÇÃO E FINANÇAS | F32: ALEXSANDRA SILVA AGUIAR E CÁSSIO ROBERTO DE SOUZA PEGORARO | G32: ISRAEL DA SILVA JUNIOR | H32: Sistema de Contabilidade, Orçamento Público e Tesouraria: WILLIAN | I32: CONTRATAÇÃO DE EMPRESA ESPECIALIZADA NA PRESTAÇÃO DE SERVIÇOS DE INFORMÁTICA, PARA O FORNECIMENTO DE LICENÇA DE SOLUÇÃO TECNOLOGICA DE GESTÃO, CONTEMPLANDO OS SERVIÇOS DE IMPLANTAÇÃO (MIGRAÇÃO DE DADOS, CUSTOMIZAÇÃO, TREINAMENTO E CAPACITAÇÃO DE USUARIOS), MANUTENÇÃO (PREVENTIVA, CORRETIVA E DE ORDEM LEGAL) E SUPORTE TÉCNICO. | J32: 24 MESES | K32: 19/07/23 a 19/07/25 | L32: 1364/22 | M32: 1601/23 | N32: 2023000000102 | O32: 2023000000357 | P32: PP 04/23 | Q32: 361000 | R32: 45471 | S32: 45140 | T32: VIGENCIA A PARTIR DA ORDEM DE SERVIÇO OCORRIDA EM 22/08/2023
H33: Sistema de Gestão de Pessoal – RH Sistema de Medicina do Trabalho Sistema de Segurança no Trabalho Sistema de Ponto Eletrônico: IASMIN | M33: 1602/23 | Q33: 193800
H34: Sistema de Administração do Patrimônio Sistema de Administração de Almoxarifados Sistema de Controle de Frota: EDUARDO | M34: 1603/23 | Q34: 142500
H35: Sistema de Administração de Compras, Licitações e Contratos: ISRAEL DA SILVA JUNIOR | M35: 1604/23 | Q35: 486200
H36: Sistema de Administração de Cemitério: Adriana Barbosa da Silva | M36: 1608/23 | Q36: 33250
H37: Sistema de Protocolo e Controle de Processos Administrativos: CARLOS | M37: 1609/23 | Q37: 47500
H38: Sistema Controle de Obras: LEILA | M38: 1582/23 | Q38: 47500
H39: Jurídico Web: Rodrigo Limettre Moreno | M39: 1266/24 | Q39: 60000
H40: Sistema de Controle Interno Portal da Transparência Lei de Acesso a Informação Sistema de Tratamento de Informações Gerenciais (Business Intelligence): EMILY CAMILA DA SILVA SANTOS | M40: 1599/23 | Q40: 128250
...

Sheet ATAS VIGENTES
A1: =TODAY() -> 46167
C2: ATA | D2: Detentor | E2: Secretaria | F2: Gestor | G2: Fiscal | H2: Objeto | I2: Modalidade | J2: Processo Administrativo | K2: Processo Execução | L2: AUDESP | M2: Valor Total Ata | N2: Assinatura | O2: Data da Publicação | P2: Vigência | S2: OBSERVAÇÃO
A3: =Q3-$A$1 -> -1 | B3: =IF(A3<60,"Vencendo","Em Vigência") -> Vencendo | C3: 12/24 | D3: PILAR ECOTEC AMBIENTAL LTDA EPP CNPJ - 30.667.156/0001-91 | E3: DESENVOLVIMENTO | F3: Tânia Maria de Oliveira Sales | G3: Cristopher Ferraz de Araujo | H3: REGISTRO DE PREÇOS VISANDO EVENTUAIS LOCAÇÃO DE ESTRUTURAS, EQUIPAMENTOS E SERVIÇOS PARA EVENTOS MUNICIPAIS | I3: PE - 08/2024 | J3: 504/2024 | K3: 992/2024 | L3: 2024000000203 | M3: 866000 | N3: 45800 | O3: 45821 | P3: 24/05/2025 A 24/05/2026 | Q3: 46166 | R3: ADITIVO
A4: =Q4-$A$1 -> -1 | B4: =IF(A4<60,"Vencendo","Em Vigência") -> Vencendo | C4: 13/24 | D4: STAGE 360 EVENTOS LTDA - EPP CNPJ - 46.429.701/0001-41 | E4: DESENVOLVIMENTO | F4: Tânia Maria de Oliveira Sales | G4: Cristopher Ferraz de Araujo | H4: REGISTRO DE PREÇOS VISANDO EVENTUAIS LOCAÇÃO DE ESTRUTURAS, EQUIPAMENTOS E SERVIÇOS PARA EVENTOS MUNICIPAIS | I4: PE - 08/2024 | J4: 504/2024 | K4: 990/2024 | L4: 2024000000203 | M4: 4190000 | N4: 45800 | O4: 45821 | P4: 24/05/2025 A 24/05/2026 | Q4: 46166 | R4: ADITIVO
A5: =Q5-$A$1 -> 1 | B5: =IF(A5<60,"Vencendo","Em Vigência") -> Vencendo | C5: 26/25 | D5: DC INFINITY COMERCIALIZADORA LTDA | E5: ADMINISTRAÇÃO | F5: Kauê Rafael Lima Di Santi Pires | G5: Eduardo da Silva Divino | H5: REGISTRO DE PREÇOS PARA FUTURA E EVENTUAL AQUISIÇÃO DE ÁGUA MINERAL NATURAL, VISANDO ATENDER AS NECESSIDADES DAS UNIDADES DA PREFEITURA MUNICIPAL DE RIO GRANDE DA SERRA | I5: PE 06/25 | J5: PE 06/25 | K5: 960/2025 | L5: 2025000000153 | M5: 41090 | N5: 45798 | O5: 45803 | P5: 26/05/2025 A 26/05/2026 | Q5: 46168
A6: =Q6-$A$1 -> 1 | B6: =IF(A6<60,"Vencendo","Em Vigência") -> Vencendo | C6: 27/25 | D6: E.S. ADMINISTRADORA LTDA | E6: ADMINISTRAÇÃO | F6: Kauê Rafael Lima Di Santi Pires | G6: Eduardo da Silva Divino | H6: REGISTRO DE PREÇOS PARA FUTURA E EVENTUAL AQUISIÇÃO DE ÁGUA MINERAL NATURAL, VISANDO ATENDER AS NECESSIDADES DAS UNIDADES DA PREFEITURA MUNICIPAL DE RIO GRANDE DA SERRA | I6: PE 06/25 | J6: PE 06/25 | K6: 961/2025 | L6: 2025000000153 | M6: 2670 | N6: 45799 | O6: 45803 | P6: 26/05/2025 A 26/05/2026 | Q6: 46168
A7: =Q7-$A$1 -> 24 | B7: =IF(A7<60,"Vencendo","Em Vigência") -> Vencendo | C7: 29/25 | D7: WINES REIS COMERCIAL LTDA CNPJ sob o nº 47.282.627/0001-46 | E7: ADMINISTRAÇÃO | F7: Israel da Silva Junior CPF: 131.326.178-57 | G7: Juventude, Esporte e Lazer Nome: José Gilmário Silva Nicolau Cargo: Chefe de Setor CPF: 155.261.668-13 Família e Desenvolvimento Social Nome: Jorge Aparecido da Silva Cargo: Motorista CPF: 061.123.038-09 Segurança Urbana, Trânsito e Defesa Civil Nome: Fabiano Gomes Duarte Cargo: Diretor CPF: 365.558.428-81 Educação e Cultura Nome: Alexandro Calazans Vieira Cargo: Chefe de Setor CPF: 293.761.318-78 Saúde Nome: Celso Paes dos Santos Cargo: Gestor CPF: 054.536.117-17 Jurídico Nome: Ariane Perogini Prestes Cargo: Agente Administrativo CPF: 303.403.088-69 Obras Nome: Guilherme Tadeu Aparecido de Oliveira Dias do Prado Cargo: Engenheiro civil CPF: 414.046.498-40 Clima, Meio ambiente e Bem Estar Animal Nome: Cláudio Fernando Pereira Cargo: Fiscal CPF: 288.291.138-67 Serviços Urbanos Nome: Guilherme Leandro Bernado Cargo: Chefe de Setor CPF: 335.305.768-40 Administração Nome: Eduardo da Silva Divino Cargo: Agente Administrativo CPF: 297.110.268-80 | H7: REGISTRO DE PREÇOS PARA CONTRATAÇÃO DE SERVIÇOS DE MANUTENÇÃO PREVENTIVA, CORRETIVA E PERIÓDICA NOS VEÍCULOS (MOTOCICLETAS, VEÍCULOS LEVES, VEÍCULOS PESADOS E MAQUINÁRIOS/ EQUIPAMENTOS PESADOS) QUE COMPÕEM A FROTA DESTE MUNICÍPIO, FORNECIMENTO OU REPOSIÇÃO DE PEÇAS E AFINS, INCLUINDO MECÂNICA EM GERAL, SERVIÇOS DE FUNILARIA, PINTURA, ELÉTRICA, HIDRÁULICA, SUSPENSÃO, CAPOTARIA, VIDRAÇARIA, BORRACHARIA, BALANCEAMENTO E ALINHAMENTO, AR CONDICIONADO, ACESSÓRIOS DE SOM E INSTALAÇÃO DE ACESSÓRIOS EM GERAL | I7: PE 05/25 | J7: 1638/2024 | K7: 1211/2025 - ADM 1810/2025 - CIDADANIA 1811/2025 - JURIDICO 1812/2025 - ESPORTE 1813/2025 - SAÚDE 1809/2025 - SEGURANÇA 1814/2025 - SSU 1815/2025 - EDUCAÇÃO 1816/2025 - MEIO AMBIENTE 1979/2025 - OBRAS | L7: 2025000000156 | M7: LOTE 01 – MOTOCICLETAS - ME/EPP R$ 16.477,50 - 50% de desconto LOTE 02 – VEÍCULOS DE PASSEIO - ME/EPP R$ 30.070,00 - 55% de desconto LOTE 03 – VEÍCULOS UTILITÁRIOS - AMPLA CONCORRÊNCIA R$ 33.840,00 - 55% de desconto LOTE 04 – VEÍCULOS PESADOS - AMPLA CONCORRÊNCIA R$ 36.597,50 - 59% de desconto LOTE 05 – MAQUINÁRIOS E EQUIPAMENTOS PESADOS - AMPLA CONCORRÊNCIA R$ 135.646,00 - 56% de desconto | N7: 45820 | O7: 45826 | P7: 18/06/2025 A 18/06/2026 | Q7: 46191
A8: =Q8-$A$1 -> 40 | B8: =IF(A8<60,"Vencendo","Em Vigência") -> Vencendo | C8: 30/25 | D8: ASTRA MEDICAL SUPPLY PRODUTOS MEDICOS E HOSPITALARES LTDA CNPJ sob o nº 44.127.150/0001-36 | E8: SAÚDE | F8: Heloisa Pereira da Silva CRF: 107757 | G8: Sara de Melo Silva Fernandes CPF: 448.006.058-81 | H8: REGISTRO DE PREÇOS DE DIETAS, ALIMENTAÇÃO ENTERAL PARA ATENDIMENTO DAS DEMANDAS JUDICIAIS DO MUNICÍPIO DE RIO GRANDE DA SERRA | I8: PE 02/25 | J8: 1886/2024 | K8: 1259/2025 | L8: 2025000000159 | M8: 13802.4 | N8: 45834 | O8: 45842 | P8: 04/07/2025 A 04/07/2026 | Q8: 46207
A9: =Q9-$A$1 -> 40 | B9: =IF(A9<60,"Vencendo","Em Vigência") -> Vencendo | C9: 31/25 | D9: FRAGNARI DISTRIBUIDORA DE MEDICAMENTOS LTDA CNPJ sob o nº 14.271.474/0001-82 | E9: SAÚDE | F9: Heloisa Pereira da Silva CRF: 107757 | G9: Sara de Melo Silva Fernandes CPF: 448.006.058-81 | H9: REGISTRO DE PREÇOS DE DIETAS, ALIMENTAÇÃO ENTERAL PARA ATENDIMENTO DAS DEMANDAS JUDICIAIS DO MUNICÍPIO DE RIO GRANDE DA SERRA | I9: PE 02/25 | J9: 1886/2024 | K9: 1260/2025 | L9: 2025000000159 | M9: 4273.2 | N9: 45826 | O9: 45842 | P9: 04/07/2025 A 04/07/2026 | Q9: 46207
A10: =Q10-$A$1 -> 40 | B10: =IF(A10<60,"Vencendo","Em Vigência") -> Vencendo | C10: 32/25 | D10: LOGGEN PRODUTOS PARA SAÚDE LTDA CNPJ sob o nº 24.980.102/0001-89 | E10: SAÚDE | F10: Heloisa Pereira da Silva CRF: 107757 | G10: Sara de Melo Silva Fernandes CPF: 448.006.058-81 | H10: REGISTRO DE PREÇOS DE DIETAS, ALIMENTAÇÃO ENTERAL PARA ATENDIMENTO DAS DEMANDAS JUDICIAIS DO MUNICÍPIO DE RIO GRANDE DA SERRA | I10: PE 02/25 | J10: 1886/2024 | K10: 1258/2025 | L10: 2025000000159 | M10: 12163.2 | N10: 45825 | O10: 45842 | P10: 04/07/2025 A 04/07/2026 | Q10: 46207
A11: =Q11-$A$1 -> 40 | B11: =IF(A11<60,"Vencendo","Em Vigência") -> Vencendo | C11: 33/25 | D11: RIOMEDICA SAÚDE E NUTRIÇÃO COMÉRCIO DE SUPLEMENTOS LTDA CNPJ sob o nº 35.578.077/0001-28 | E11: SAÚDE | F11: Heloisa Pereira da Silva CRF: 107757 | G11: Sara de Melo Silva Fernandes CPF: 448.006.058-81 | H11: REGISTRO DE PREÇOS DE DIETAS, ALIMENTAÇÃO ENTERAL PARA ATENDIMENTO DAS DEMANDAS JUDICIAIS DO MUNICÍPIO DE RIO GRANDE DA SERRA | I11: PE 02/25 | J11: 1886/2024 | K11: 1257/2025 | L11: 2025000000159 | M11: 4315.2 | N11: 45826 | O11: 45842 | P11: 04/07/2025 A 04/07/2026 | Q11: 46207
A12: =Q12-$A$1 -> 59 | B12: =IF(A12<60,"Vencendo","Em Vigência") -> Vencendo | C12: 37/25 | D12: TREVO PADARIA RESTAURANTE E PIZZARIA LTDA CNPJ sob o nº 60.163.707/000-40 | E12: CIDADANIA | F12: Fernanda Stachowski CPF: 336.725.538-67 | G12: Cibely Aparecida Miranda dos Santos CPF: 462.455.488-45 | H12: REGISTRO DE PREÇOS PARA EVENTUAL FORNECIMENTO DE REFEIÇÕES, SENDO DESJEJUM E JANTAR (MARMITEX), PARA ATENDIMENTO ÀS PESSOAS EM SITUAÇÃO DE RUA, REFERENCIADAS E ACOMPANHADAS PELA EQUIPE DO CREAS | I12: DP 13/25 | J12: 2117/2023 | K12: 1460/2025 | L12: 2025000000166 | M12: 95400 | N12: 45860 | O12: 45861 | P12: 23/07/2025 A 23/07/2026 | Q12: 46226
A13: =Q13-$A$1 -> 68 | B13: =IF(A13<60,"Vencendo","Em Vigência") -> Em Vigência | C13: 38/25 | D13: COMERCIAL PROMOSTORE CONFECCOES LTDA CNPJ sob o nº 32.624.131/0001-36 | E13: EDUCAÇÃO | F13: Mônica Mara Rodrigues CPF: 257.494.078-45 | G13: Paula Neves Bernardo Garcia CPF: 163.539.478-36 | H13: REGISTRO DE PREÇOS VISANDO ADQUIRIR MATERIAL DE APOIO PEDAGÓGICO PARA ATENDER AS DEMANDAS ESCOLARES E DOS ALUNOS DA REDE MUNICIPAL DE ENSINO NO MUNICÍPIO DE RIO GRANDE DA SERRA | I13: PE 01/24 | J13: 1907/2023 | K13: 1408/2025 | L13: 2025000000169 | M13: 105117.4 | N13: 45867 | O13: 45870 | P13: 01/08/2025 A 01/08/2026 | Q13: 46235
A14: =Q14-$A$1 -> 59 | B14: =IF(A14<60,"Vencendo","Em Vigência") -> Vencendo | C14: 39/25 | D14: ESC COMERCIAL LTDA CNPJ sob o nº 42.222.413/0001-60 | E14: EDUCAÇÃO | F14: Mônica Mara Rodrigues CPF: 257.494.078-45 | G14: Paula Neves Bernardo Garcia CPF: 163.539.478-36 | H14: REGISTRO DE PREÇOS VISANDO ADQUIRIR MATERIAL DE APOIO PEDAGÓGICO PARA ATENDER AS DEMANDAS ESCOLARES E DOS ALUNOS DA REDE MUNICIPAL DE ENSINO NO MUNICÍPIO DE RIO GRANDE DA SERRA | I14: PE 01/24 | J14: 1907/2023 | K14: 1409/2025 | L14: 2025000000169 | M14: 1243407.2 | N14: 45856 | O14: 45861 | P14: 23/07/2025 A 23/07/2026 | Q14: 46226
A15: =Q15-$A$1 -> 59 | B15: =IF(A15<60,"Vencendo","Em Vigência") -> Vencendo | C15: 40/25 | D15: S A FREITAS ARTIGOS DE ESCRITORIO LTDA CNPJ sob o nº 48.547.677/0001-70 | E15: EDUCAÇÃO | F15: Mônica Mara Rodrigues CPF: 257.494.078-45 | G15: Paula Neves Bernardo Garcia CPF: 163.539.478-36 | H15: REGISTRO DE PREÇOS VISANDO ADQUIRIR MATERIAL DE APOIO PEDAGÓGICO PARA ATENDER AS DEMANDAS ESCOLARES E DOS ALUNOS DA REDE MUNICIPAL DE ENSINO NO MUNICÍPIO DE RIO GRANDE DA SERRA | I15: PE 01/24 | J15: 1907/2023 | K15: 1410/2025 | L15: 2025000000169 | M15: 285474.43 | N15: 45855 | O15: 45861 | P15: 23/07/2025 A 23/07/2026 | Q15: 46226
A16: =Q16-$A$1 -> 64 | B16: =IF(A16<60,"Vencendo","Em Vigência") -> Em Vigência | C16: 41/25 | D16: SEVEN COMERCIO E SERVIÇOS LTDA CNPJ sob o nº 07.159.856/0001-53 | E16: EDUCAÇÃO | F16: Mônica Mara Rodrigues CPF: 257.494.078-45 | G16: Paula Neves Bernardo Garcia CPF: 163.539.478-36 | H16: REGISTRO DE PREÇOS VISANDO ADQUIRIR MATERIAL DE APOIO PEDAGÓGICO PARA ATENDER AS DEMANDAS ESCOLARES E DOS ALUNOS DA REDE MUNICIPAL DE ENSINO NO MUNICÍPIO DE RIO GRANDE DA SERRA | I16: PE 01/24 | J16: 1907/2023 | K16: 1411/2025 | L16: 2025000000169 | M16: 649690 | N16: 45861 | O16: 45866 | P16: 28/07/2025 A 28/07/2026 | Q16: 46231
A17: =Q17-$A$1 -> 74 | B17: =IF(A17<60,"Vencendo","Em Vigência") -> Em Vigência | C17: 42/25 | D17: ROSICLER CIRURGICA LTDA CNPJ Nº: nº 57.365.116/0001-41 | E17: CIDADANIA | F17: Cibely Aparecida Miranda dos Santos CPF: 462.455.488-45 | G17: Ilana Rodrigues Mariano CPF: 318.605.163-00 | H17: REGISTRO DE PREÇOS, VISANDO A EVENTUAL FÓRMULA LÁCTEA INFANTIL, PARA ATENDER AS DEMANDAS DO SAICA (SERVIÇO DE ACOLHIMENTO INSTITUCIONAL PARA CRIANÇAS E ADOLESCENTES). | I17: PE 20/25 | J17: 162/2025 | K17: 1545/2025 | L17: 2025000000171 | M17: 38334 | N17: 45873 | O17: 45876 | P17: 07/08/2025 A 07/08/2026 | Q17: 46241
A18: =Q18-$A$1 -> 74 | B18: =IF(A18<60,"Vencendo","Em Vigência") -> Em Vigência | C18: 43/25 | D18: BERITH COMERCIO DE PRODUTOS ODONTOLOGICOS LTDA CNPJ sob o nº 57.642.694/0001-88 | E18: CIDADANIA | F18: Gerlice Brasil da Silva CPF: 270.446.548-78 | G18: Silvana Moraes Branco Conceição CPF: 140.431.098-30 | H18: REGISTRO DE PREÇO DE MATERIAIS ODONTOLÓGICOS PARA ATENDER AS NECESSIDADES DAS UNIDADES QUE COMPÕEM A SECRETARIA DE SAÚDE DO MUNICÍPIO DE RIO GRANDE DA SERRA | I18: PE 13/25 | J18: 2003/2024 | K18: 1546/2025 | L18: 2025000000171 | M18: 7948.41 | N18: 45873 | O18: 45876 | P18: 07/08/2025 A 07/08/2026 | Q18: 46241
A19: =Q19-$A$1 -> 74 | B19: =IF(A19<60,"Vencendo","Em Vigência") -> Em Vigência | C19: 44/25 | D19: DENTAL CONCEITO COMERCIO DE PRODUTOS ODONTOLOGICOS MEDICOS E HOSPITALARES LTDA CNPJ Nº: nº 29.084.363/0001-34 | E19: SAÚDE | F19: Gerlice Brasil da Silva CPF: 270.446.548-78 | G19: Silvana Moraes Branco Conceição CPF: 140.431.098-30 | H19: REGISTRO DE PREÇO DE MATERIAIS ODONTOLÓGICOS PARA ATENDER AS NECESSIDADES DAS UNIDADES QUE COMPÕEM A SECRETARIA DE SAÚDE DO MUNICÍPIO DE RIO GRANDE DA SERRA | I19: PE 13/25 | J19: 2003/2024 | K19: 1521/2025 | L19: 2025000000171 | M19: 27807.3 | N19: 45867 | O19: 45876 | P19: 07/08/2025 A 07/08/2026 | Q19: 46241
... A30: =Q30-$A$1 -> 89 | B30: =IF(A30<60,"Vencendo","Em Vigência") -> Em Vigência | C30: 55/25 | D30: ALMEIDA FARMACEUTICA LTDA CNPJ sob o nº 40.455.009/0001-01 | E30: SAÚDE | F30: Heloisa Pereira da Silva CPF: 434.113.338-12 | G30: Demóstenes Dias de Mendonça CPF: 460.198.395-91 | H30: REGISTRO DE PREÇOS PARA AQUISIÇÃO DE MEDICAMENTOS FRACASSADOS/DESERTOS EM PREGÕES ANTERIORES PARA ATENDER AS NECESSIDADES DAS UNIDADES QUE COMPÕEM A SECRETARIA DE SAÚDE DA PREFEITURA MUNICIPAL DE RIO GRANDE DA SERRA | I30: PE 12/25 | J30: 307/2025 | K30: 1691/2025 | L30: 2025000000184 | M30: 158388 | N30: 45888 | O30: 45891 | P30: 22/08/2025 A 22/08/2026 | Q30: 46256
A31: =Q31-$A$1 -> 93 | B31: =IF(A31<60,"Vencendo","Em Vigência") -> Em Vigência | C31: 27/24 | D31: ATMOSFERA GASES ESPECIAIS E EPIS CNPJ - 13.134.213/0001-58 | E31: SAÚDE | F31: FELIPE VIEIRA DE SÁ DOS SANTOS | G31: GERLICE BRASIL DA SILVA | H31: REGISTRO DE PREÇO PARA TROCA E FORNECIMENTO CONTÍNUO ININTERRUPTO DE OXIGÊNIO GASOSO, COM SISTEMA DE COMODATO EM CILINDROS, PARA SUPRIR AS NECESSIDADES DA SECRETARIA DE SAÚDE, COM A ENTREGA SOB DEMANDA, PELO PERÍODO DE 24 (VINTE E QUATRO MESES). | I31: PE - 20/24 | J31: 45444 | K31: 1639/2024 | L31: 2024000000228 | M31: 2025000 | N31: 45530 | O31: 45530 | P31: 26/08/2024 A 26/08/2025 | Q31: 46260
B32: =IF(A32<60,"Vencendo","Em Vigência") -> Vencendo | C32: ADITIVO | F32: TELMA MORAES PIRES | G32: GERLICE BRASIL DA SILVA | M32: 2025000 | N32: 45895 | O32: 45910 | P32: 26/08/2025 a 26/08/2026
A33: =Q33-$A$1 -> 94 | B33: =IF(A33<60,"Vencendo","Em Vigência") -> Em Vigência | C33: 56/25 | D33: APOTEK DISTRIBUIDORA DE MEDICAMENTOS E MATERIAIS HOSPITALARES LTDA CNPJ sob o nº 36.099.392/0001-35 | E33: SAÚDE | F33: Heloisa Pereira da Silva CPF: 434.113.338-12 | G33: Demóstenes Dias de Mendonça CPF: 460.198.395-91 | H33: REGISTRO DE PREÇOS PARA AQUISIÇÃO DE MEDICAMENTOS FRACASSADOS/DESERTOS EM PREGÕES ANTERIORES PARA ATENDER AS NECESSIDADES DAS UNIDADES QUE COMPÕEM A SECRETARIA DE SAÚDE DA PREFEITURA MUNICIPAL DE RIO GRANDE DA SERRA | I33: PE 12/25 | J33: 307/2025 | K33: 1692/2025 | L33: 2025000000184 | M33: 64632 | N33: 45894 | O33: 45896 | P33: 27/08/2025 A 27/08/2026 | Q33: 46261
A34: =Q34-$A$1 -> 114 | B34: =IF(A34<60,"Vencendo","Em Vigência") -> Em Vigência | C34: 57/25 | D34: AZULFARMA DISTRIBUIDORA DE MEDICAMENTOS LTDA CNPJ sob o nº 03.634.617/0001-57 | E34: SAÚDE | F34: Heloisa Pereira da Silva CPF: 434.113.338-12 | G34: Demóstenes Dias de Mendonça CPF: 460.198.395-91 | H34: REGISTRO DE PREÇOS PARA AQUISIÇÃO DE MEDICAMENTOS FRACASSADOS/DESERTOS EM PREGÕES ANTERIORES PARA ATENDER AS NECESSIDADES DAS UNIDADES QUE COMPÕEM A SECRETARIA DE SAÚDE DA PREFEITURA MUNICIPAL DE RIO GRANDE DA SERRA | I34: PE 12/25 | J34: 307/2025 | K34: 1828/2025 | L34: 2025000000184 | M34: 39636 | N34: 45910 | O34: 45916 | P34: 16/09/2025 A 16/09/2026 | Q34: 46281
A35: =Q35-$A$1 -> 102 | B35: =IF(A35<60,"Vencendo","Em Vigência") -> Em Vigência | C35: 58/25 | D35: CIRÚRGICA OLÍMPIO LTDA CNPJ sob o nº 01.140.868/0001-50 | E35: SAÚDE | F35: Heloisa Pereira da Silva CPF: 434.113.338-12 | G35: Demóstenes Dias de Mendonça CPF: 460.198.395-91 | H35: REGISTRO DE PREÇOS PARA AQUISIÇÃO DE MEDICAMENTOS FRACASSADOS/DESERTOS EM PREGÕES ANTERIORES PARA ATENDER AS NECESSIDADES DAS UNIDADES QUE COMPÕEM A SECRETARIA DE SAÚDE DA PREFEITURA MUNICIPAL DE RIO GRANDE DA SERRA | I35: PE 12/25 | J35: 307/2025 | K35: 1693/2025 | L35: 2025000000184 | M35: 27600 | N35: 45887 | O35: 45904 | P35: 04/09/2025 A 04/09/2026 | Q35: 46269
A36: =Q36-$A$1 -> 107 | B36: =IF(A36<60,"Vencendo","Em Vigência") -> Em Vigência | C36: 59/25 | D36: CIRÚRGICA ASSIS DISTRIBUIDORA DE PRODUTOS PARA SAÚDE LTDA CNPJ sob o nº 39.610.184/0001-47 | E36: SAÚDE | F36: Heloisa Pereira da Silva CPF: 434.113.338-12 | G36: Demóstenes Dias de Mendonça CPF: 460.198.395-91 | H36: REGISTRO DE PREÇOS PARA AQUISIÇÃO DE MEDICAMENTOS FRACASSADOS/DESERTOS EM PREGÕES ANTERIORES PARA ATENDER AS NECESSIDADES DAS UNIDADES QUE COMPÕEM A SECRETARIA DE SAÚDE DA PREFEITURA MUNICIPAL DE RIO GRANDE DA SERRA | I36: PE 12/25 | J36: 307/2025 | K36: 1694/2025 | L36: 2025000000184 | M36: 5976 | N36: 45902 | O36: 45909 | P36: 09/09/2025 A 09/09/2026 | Q36: 46274
A37: =Q37-$A$1 -> 94 | B37: =IF(A37<60,"Vencendo","Em Vigência") -> Em Vigência | C37: 60/25 | D37: CIRÚRGICA NOSSA SENHORA LTDA CNPJ sob o nº 24.586.988/0001-80 | E37: SAÚDE | F37: Heloisa Pereira da Silva CPF: 434.113.338-12 | G37: Demóstenes Dias de Mendonça CPF: 460.198.395-91 | H37: REGISTRO DE PREÇOS PARA AQUISIÇÃO DE MEDICAMENTOS FRACASSADOS/DESERTOS EM PREGÕES ANTERIORES PARA ATENDER AS NECESSIDADES DAS UNIDADES QUE COMPÕEM A SECRETARIA DE SAÚDE DA PREFEITURA MUNICIPAL DE RIO GRANDE DA SERRA | I37: PE 12/25 | J37: 307/2025 | K37: 1695/2025 | L37: 2025000000184 | M37: 19557 | N37: 45889 | O37: 45896 | P37: 27/08/2025 A 27/08/2026 | Q37: 46261
A38: =Q38-$A$1 -> 89 | B38: =IF(A38<60,"Vencendo","Em Vigência") -> Em Vigência | C38: 61/25 | D38: COMERCIAL CIRÚRGICA RIOCLARENSE LTDA CNPJ sob o nº 67.729.178/0004-91 | E38: SAÚDE | F38: Heloisa Pereira da Silva CPF: 434.113.338-12 | G38: Demóstenes Dias de Mendonça CPF: 460.198.395-91 | H38: REGISTRO DE PREÇOS PARA AQUISIÇÃO DE MEDICAMENTOS FRACASSADOS/DESERTOS EM PREGÕES ANTERIORES PARA ATENDER AS NECESSIDADES DAS UNIDADES QUE COMPÕEM A SECRETARIA DE SAÚDE DA PREFEITURA MUNICIPAL DE RIO GRANDE DA SERRA | I38: PE 12/25 | J38: 307/2025 | K38: 1696/2025 | L38: 2025000000184 | M38: 156426 | N38: 45888 | O38: 45891 | P38: 22/08/2025 A 22/08/2026 | Q38: 46256
